Workbook

Sheet Genera A
A1: Dr.Rafiq Zakaria Campus
A2: Maulana Azad Complex of Hostel
A3: Dr.Rafiq Zakaria Marg, Rauza Bagh, Aurangabad
A4: Individual Register (General Students) for the Academic Year 2025 - 2026 'A' Wing
A5: Sr.No | B5: Name of Student & Mobile | C5: Wing & Room | D5: Class | E5: Date of Joining | F5: Receipt No. | G5: Receipt Date | H5: Regi. Fee | I5: Room Rent | J5: Water & Electricity Charges | K5: Other Activity | L5: Total Fees Collection | M5: Approved Hostel Fees | N5: Outstanding Fee | O5: Remark | P5: Security Deposit
A6: 1 | B6: Uzair Khan Pathan Aslam Khan, at. Shah Inayat Mohalla Gandhipark Parbhani, 9028974366,9890371395 | C6: A-12 | D6: B.Com.I | E6: 27.06.2025 to 27.04.2026 | F6: 6742 | G6: 27.06.2025 | H6: 500 | I6: 11000 | J6: 3000 | L6: =SUM(H6:K6) -> 14500 | M6: 17500 | O6: UPI | P6: 1500
L7: =SUM(H7:K7) -> 0
L8: =SUM(H8:K8) -> 0
L9: =SUM(H9:K9) -> 0
L10: =SUM(H10:K10) -> 0
H11: =SUM(H6:H10) -> 500 | I11: =SUM(I6:I10) -> 11000 | J11: =SUM(J6:J10) -> 3000 | K11: =SUM(K6:K10) -> 0 | L11: =SUM(L6:L10) -> 14500 | N11: =M6-L11 -> 3000 | P11: =SUM(P6:P10) -> 1500
A12: 2 | B12: Shaikh Sajid Shaikh Taslim, at, Dhamangaon Badhe, Dist. Buldhana, 9511606098, 7385131389 | C12: A-01 | D12: B.Sc.I | E12: 08.07.2025 to 09.05.2026 | F12: 6772 | G12: 08.07.2025 | H12: 500 | I12: 14000 | J12: 3000 | L12: =SUM(H12:K12) -> 17500 | M12: 17500 | O12: UPI | P12: 1500
L13: =SUM(H13:K13) -> 0
L14: =SUM(H14:K14) -> 0
L15: =SUM(H15:K15) -> 0
L16: =SUM(H16:K16) -> 0
H17: =SUM(H12:H16) -> 500 | I17: =SUM(I12:I16) -> 14000 | J17: =SUM(J12:J16) -> 3000 | K17: =SUM(K12:K16) -> 0 | L17: =SUM(L12:L16) -> 17500 | N17: =M12-L17 -> 0 | P17: =SUM(P12:P16) -> 1500
A18: =A12+1 -> 3 | B18: Pathan Arman Bismilla Modha Khurd tq. Sillod dist. Aurangabad 8308135883 | C18: A-01 | D18: B.Sc II Year | E18: 02.06.2025 to 03.04.2026 | F18: 6789 | G18: 14.07.2025 | H18: 500 | I18: 4500 | L18: =SUM(H18:K18) -> 5000 | M18: 17500 | O18: Old Student
L19: =SUM(H19:K19) -> 0
L20: =SUM(H20:K20) -> 0
L21: =SUM(H21:K21) -> 0
L22: =SUM(H22:K22) -> 0
H23: =SUM(H18:H22) -> 500 | I23: =SUM(I18:I22) -> 4500 | J23: =SUM(J18:J22) -> 0 | K23: =SUM(K18:K22) -> 0 | L23: =SUM(L18:L22) -> 5000 | N23: =M18-L23 -> 12500 | P23: =SUM(P18:P22) -> 0
A24: =A18+1 -> 4 | B24: Mohammed Saad Javed Ansari, at. Fazalpura, Aurangabad, 9975372664, 9923339333 | C24: A-12 | D24: XI th Sci. | E24: 23.07.2025 to 23.05.2026 | F24: 6825 | G24: 24.07.2025 | H24: 500 | I24: 11000 | J24: 3000 | L24: =SUM(H24:K24) -> 14500 | M24: 17500 | P24: 1500
L25: =SUM(H25:K25) -> 0
L26: =SUM(H26:K26) -> 0
L27: =SUM(H27:K27) -> 0
L28: =SUM(H28:K28) -> 0
H29: =SUM(H24:H28) -> 500 | I29: =SUM(I24:I28) -> 11000 | J29: =SUM(J24:J28) -> 3000 | K29: =SUM(K24:K28) -> 0 | L29: =SUM(L24:L28) -> 14500 | N29: =M24-L29 -> 3000 | P29: =SUM(P24:P28) -> 1500
A30: 5 | B30: Abdul Hakam Siddiqui, at. Plot. No. 6, Dhar Road, Mumtaz Nagar, Parbhani, 9021810132, 9421557406 | C30: A-02 | D30: Evrest B.E. Ist | E30: 17.09.2025 to 17.07.2026 | F30: 6877 | G30: 15.08.2025 | H30: 500 | I30: 14000 | J30: 3000 | L30: =SUM(H30:K30) -> 17500 | M30: 17500 | P30: 1500
L31: =SUM(H31:K31) -> 0
L32: =SUM(H32:K32) -> 0
L33: =SUM(H33:K33) -> 0
L34: =SUM(H34:K34) -> 0
H35: =SUM(H30:H34) -> 500 | I35: =SUM(I30:I34) -> 14000 | J35: =SUM(J30:J34) -> 3000 | K35: =SUM(K30:K34) -> 0 | L35: =SUM(L30:L34) -> 17500 | N35: =M30-L35 -> 0 | P35: =SUM(P30:P34) -> 1500
A36: =A30+1 -> 6 | B36: Pathan Abubakar Kha Gaus Kha, at. Kunjkheda, Kannad, 8830737773,9420812816 | C36: A-16 | D36: B.Sc. Biotech II | E36: 03.05.2025 to 03.03.2026 | F36: 6879 | G36: 18.08.2025 | H36: 500 | I36: 6500 | J36: 3000 | L36: =SUM(H36:K36) -> 10000 | M36: 17500 | O36: Old Student
L37: =SUM(H37:K37) -> 0
L38: =SUM(H38:K38) -> 0
L39: =SUM(H39:K39) -> 0
L40: =SUM(H40:K40) -> 0
...

Sheet Individual Register 2025-2026
A1: Dr.Rafiq Zakaria Campus
A2: Maulana Azad Complex of Hostel
A3: Dr.Rafiq Zakaria Marg, Rauza Bagh, Aurangabad
A4: Individual Register (General Students) for the Academic Year 2025 - 2026 'B' Wing
A5: Sr.No | B5: Name of Student & Mobile | C5: Wing & Room | D5: Class | E5: Date of Joining | F5: Receipt No. | G5: Receipt Date | H5: Regi. Fee | I5: Room Rent | J5: Water & Electricity Charges | K5: Other Activity | L5: Total Fees Collection | M5: Approved Hostel Fees | N5: Outstanding Fee | O5: Remark | P5: Security Deposit
A6: 1 | B6: Umershahkhan Jaber Shahkhan, at. Dhawda Tq.Bhokardan, Jalna, 8888546467, 9860656367 | C6: B-07 | D6: Govt. Medical College A.bad. Lab.Tech.I | E6: 01.05.2025 to 01.03.2026 | F6: 6712 | G6: 06.05.2025 | H6: 500 | I6: 4500 | L6: =SUM(H6:K6) -> 5000 | M6: 14500 | O6: Old Student
F7: 6962 | G7: 16.09.2025 | I7: 2000 | J7: 3000 | L7: =SUM(H7:K7) -> 5000
L8: =SUM(H8:K8) -> 0
L9: =SUM(H9:K9) -> 0
L10: =SUM(H10:K10) -> 0
H11: =SUM(H6:H10) -> 500 | I11: =SUM(I6:I10) -> 6500 | J11: =SUM(J6:J10) -> 3000 | K11: =SUM(K6:K10) -> 0 | L11: =SUM(L6:L10) -> 10000 | N11: =M6-L11 -> 4500 | P11: =SUM(P6:P10) -> 0
A12: =A6+1 -> 2 | B12: Mohammad Zabihullah Mohammad Hashmatullah Mansoori, Nalasupara west Mumbai, 9209899478, 9819256114 | C12: C-31 | D12: XII Sci. | E12: 03.05.2025 to 03.03.2026 | F12: 6682 | G12: 19.05.2025 | H12: 500 | I12: 4000 | J12: 3000 | L12: =SUM(H12:K12) -> 7500 | M12: 14500 | O12: UPI
F13: 6888 | G13: 20.08.2025 | I13: 3000 | L13: =SUM(H13:K13) -> 3000 | O13: Old Student
L14: =SUM(H14:K14) -> 0
L15: =SUM(H15:K15) -> 0
L16: =SUM(H16:K16) -> 0
H17: =SUM(H12:H16) -> 500 | I17: =SUM(I12:I16) -> 7000 | J17: =SUM(J12:J16) -> 3000 | K17: =SUM(K12:K16) -> 0 | L17: =SUM(L12:L16) -> 10500 | N17: =M12-L17 -> 4000 | P17: =SUM(P12:P16) -> 0
A18: =A12+1 -> 3 | B18: Atif Iqbal Mansuri, at chawl No. 01 kalyan Est, 9076510254, 9819476994 | C18: C-22 | D18: B.Com.I | E18: 23.06.2025 to 23.04.2026 | F18: 6700 | G18: 23.06.2025 | H18: 500 | I18: 2000 | J18: 3000 | L18: =SUM(H18:K18) -> 5500 | M18: 14500 | P18: 1500
F19: 6771 | G19: 07.07.2025 | I19: 4000 | L19: =SUM(H19:K19) -> 4000
F20: 6821 | G20: 23.07.2025 | I20: 5000 | L20: =SUM(H20:K20) -> 5000
L21: =SUM(H21:K21) -> 0
L22: =SUM(H22:K22) -> 0
H23: =SUM(H18:H22) -> 500 | I23: =SUM(I18:I22) -> 11000 | J23: =SUM(J18:J22) -> 3000 | K23: =SUM(K18:K22) -> 0 | L23: =SUM(L18:L22) -> 14500 | N23: =M18-L23 -> 0 | P23: =SUM(P18:P22) -> 1500
A24: =A18+1 -> 4 | B24: Mohammad Farhan Ahemad,Abdul Razzaque, at Arman Colony, eulgaon Raja, Dist. Buldhana, 9405778487,9595187487 | C24: C-30 | D24: XIIth Sci. | E24: 08.05.2025 to 08.03.2026 | F24: 6698 | G24: 20.06.2025 | H24: 500 | I24: 3500 | L24: =SUM(H24:K24) -> 4000 | M24: 14500 | O24: Old Student
F25: 9823 | G25: 23.07.2025 | I25: 2000 | J25: 3000 | L25: =SUM(H25:K25) -> 5000
F26: 6977 | G26: 21.09.2025 | I26: 5500 | L26: =SUM(H26:K26) -> 5500
L27: =SUM(H27:K27) -> 0
L28: =SUM(H28:K28) -> 0
H29: =SUM(H24:H28) -> 500 | I29: =SUM(I24:I28) -> 11000 | J29: =SUM(J24:J28) -> 3000 | K29: =SUM(K24:K28) -> 0 | L29: =SUM(L24:L28) -> 14500 | N29: =M24-L29 -> 0 | P29: =SUM(P24:P28) -> 0
A30: =A24+1 -> 5 | B30: Shaikh Khizar Ali, at Sher ali chowk, Buldhana, 9923504849 | C30: B-06 | D30: Xith Sci. | E30: 05.07.2025 to 05.05.2026 | F30: 6695 | G30: 14.06.2025 | H30: 500 | I30: 3000 | L30: =SUM(H30:K30) -> 3500 | M30: 14500 | P30: 1500
F31: 6992 | G31: 26.09.2025 | I31: 2000 | J31: 3000 | L31: =SUM(H31:K31) -> 5000
L32: =SUM(H32:K32) -> 0
L33: =SUM(H33:K33) -> 0
L34: =SUM(H34:K34) -> 0
H35: =SUM(H30:H34) -> 500 | I35: =SUM(I30:I34) -> 5000 | J35: =SUM(J30:J34) -> 3000 | K35: =SUM(K30:K34) -> 0 | L35: =SUM(L30:L34) -> 8500 | N35: =M30-L35 -> 6000 | P35: =SUM(P30:P34) -> 1500
A36: =A30+1 -> 6 | B36: Shaikh Mudassir Jameel, at. Teachers Colony Paratwada, Achalpur, 7666635832, 9552871992 | C36: C-32 | D36: Neet Class | E36: 09.06.2025 to 09.04.2026 | F36: 6692 | G36: 09.06.2025 | H36: 500 | I36: 3000 | J36: 3000 | L36: =SUM(H36:K36) -> 6500 | M36: 14500 | O36: UPI | P36: 1500
L37: =SUM(H37:K37) -> 0
L38: =SUM(H38:K38) -> 0
L39: =SUM(H39:K39) -> 0
L40: =SUM(H40:K40) -> 0
...

Sheet D.Pharm  (A)
A1: Dr.Rafiq Zakaria Campus
A2: Maulana Azad Complex of Hostel
A3: Dr.Rafiq Zakaria Marg, Rauza Bagh, Aurangabad
A4: Individual Register (D.Pharm) for the Academic Year 2025 - 2026 'A' Wing
A5: Sr.No | B5: Name of Student & Mobile | C5: Wing & Room | D5: Class | E5: Date of Joining | F5: Receipt No. | G5: Receipt Date | H5: Regi. Fee | I5: Room Rent | J5: Water & Electricity Charges | K5: Other Activity | L5: Total Fees Collection | M5: Approved Hostel Fees | N5: Outstanding Fee | O5: Remark | P5: Security Deposit
A6: 1 | L6: =SUM(H6:K6) -> 0
L7: =SUM(H7:K7) -> 0
L8: =SUM(H8:K8) -> 0
L9: =SUM(H9:K9) -> 0
L10: =SUM(H10:K10) -> 0
H11: =SUM(H6:H10) -> 0 | I11: =SUM(I6:I10) -> 0 | J11: =SUM(J6:J10) -> 0 | K11: =SUM(K6:K10) -> 0 | L11: =SUM(L6:L10) -> 0 | N11: =M6-L11 -> 0
A12: 2 | L12: =SUM(H12:K12) -> 0
L13: =SUM(H13:K13) -> 0
L14: =SUM(H14:K14) -> 0
L15: =SUM(H15:K15) -> 0
L16: =SUM(H16:K16) -> 0
F17: Total | H17: =SUM(H12:H16) -> 0 | I17: =SUM(I12:I16) -> 0 | J17: =SUM(J12:J16) -> 0 | K17: =SUM(K12:K16) -> 0 | L17: =SUM(L12:L16) -> 0 | N17: =M12-L17 -> 0 | O17: UTR | P17: =SUM(P12:P16) -> 0
A18: Total Fees Collection | H18: =+H11+H17 -> 0 | I18: =+I11+I17 -> 0 | J18: =+J11+J17 -> 0 | K18: =+K11+K17 -> 0 | L18: =+L11+L17 -> 0 | M18: =+M6+M12 -> 0 | N18: =+N11+N17 -> 0 | P18: =+P11+P17 -> 0

Sheet D.Pharm (B)
A1: Dr.Rafiq Zakaria Campus
A2: Maulana Azad Complex of Hostel
A3: Dr.Rafiq Zakaria Marg, Rauza Bagh, Aurangabad
A4: Individual Register (D.Pharm) for the Academic Year 2025 - 2026 'B' Wing
A5: Sr.No | B5: Name of Student & Mobile | C5: Wing & Room | D5: Class | E5: Date of Joining | F5: Receipt No. | G5: Receipt Date | H5: Regi. Fee | I5: Room Rent | J5: Water & Electricity Charges | K5: Other Activity | L5: Total Fees Collection | M5: Approved Hostel Fees | N5: Outstanding Fee | O5: Remark | P5: Security Deposit
A6: 1 | B6: Onkar Haribhau More, at. Bagpimpalgao, Dist. Beed, 8080398092, 8999448434 | C6: C-10 | D6: D.Pharm II | E6: 30.06.20225 to 30.04.2026 | F6: 6747 | G6: 30.06.2025 | H6: 500 | I6: 3000 | J6: 3000 | L6: =SUM(H6:K6) -> 6500 | M6: 14500 | O6: UPI | P6: 1500
L7: =SUM(H7:K7) -> 0
L8: =SUM(H8:K8) -> 0
L9: =SUM(H9:K9) -> 0
L10: =SUM(H10:K10) -> 0
H11: =SUM(H6:H10) -> 500 | I11: =SUM(I6:I10) -> 3000 | J11: =SUM(J6:J10) -> 3000 | K11: =SUM(K6:K10) -> 0 | L11: =SUM(L6:L10) -> 6500 | N11: =M6-L11 -> 8000 | P11: =SUM(P6:P10) -> 1500
A12: 2 | B12: Kunal Subhash Pardhe, at Shahagad, Jalna, 9420923209,9637579606 | C12: C-10 | D12: D.Pharm II | E12: 30.06.20225 to 30.04.2026 | F12: 6746 | G12: 30.06.2025 | H12: 500 | I12: 11000 | J12: 3000 | L12: =SUM(H12:K12) -> 14500 | M12: 14500 | O12: UPI | P12: 1500
L13: =SUM(H13:K13) -> 0
L14: =SUM(H14:K14) -> 0
L15: =SUM(H15:K15) -> 0
L16: =SUM(H16:K16) -> 0
H17: =SUM(H12:H16) -> 500 | I17: =SUM(I12:I16) -> 11000 | J17: =SUM(J12:J16) -> 3000 | K17: =SUM(K12:K16) -> 0 | L17: =SUM(L12:L16) -> 14500 | N17: =M12-L17 -> 0 | P17: =SUM(P12:P16) -> 1500
A18: 3 | B18: Sayyed Rehan Ali Sayyed Riyaz Ali, At.Amardas Nagar, Risod, Dist,Washim, 9850272281,7057177353 | C18: D-01 | D18: D.Pharm II | E18: 19.07.2025 to 19.05.2026 | F18: 6942 | G18: 11.09.2025 | H18: 500 | I18: 4500 | J18: 3000 | L18: =SUM(H18:K18) -> 8000 | M18: 14500 | O18: Old Student
L19: =SUM(H19:K19) -> 0
L20: =SUM(H20:K20) -> 0
L21: =SUM(H21:K21) -> 0
L22: =SUM(H22:K22) -> 0
H23: =SUM(H18:H22) -> 500 | I23: =SUM(I18:I22) -> 4500 | J23: =SUM(J18:J22) -> 3000 | K23: =SUM(K18:K22) -> 0 | L23: =SUM(L18:L22) -> 8000 | N23: =M18-L23 -> 6500 | P23: =SUM(P18:P22) -> 0
A24: 4 | B24: Sayyed Farhan Sayyed Bhshir, At. Undangaon, Tq. Sillod.Dist. Aurangabad., 9579398103, 9921389617 | C24: C-10 | D24: D-Pharm II | E24: 17.09.2025 to 17.07.2026 | F24: 6976 | G24: 20.09.2025 | H24: 500 | I24: 4500 | J24: 3000 | L24: =SUM(H24:K24) -> 8000 | M24: 14500 | O24: Old Student
L25: =SUM(H25:K25) -> 0
L26: =SUM(H26:K26) -> 0
L27: =SUM(H27:K27) -> 0
L28: =SUM(H28:K28) -> 0
H29: =SUM(H24:H28) -> 500 | I29: =SUM(I24:I28) -> 4500 | J29: =SUM(J24:J28) -> 3000 | K29: =SUM(K24:K28) -> 0 | L29: =SUM(L24:L28) -> 8000 | N29: =M24-L29 -> 6500 | P29: =SUM(P24:P28) -> 0
A30: 5 | B30: Arshad Khan Babar Khan, at. Shersawar Nagar Old Jalna, 9579959524,9860414784 | C30: C-10 | D30: D-Pharm II | E30: 12.10.2025 to 12.08.2025 | F30: 7081 | G30: 13.11.2025 | H30: 500 | I30: 4500 | J30: 3000 | L30: =SUM(H30:K30) -> 8000 | M30: 14500 | O30: Old Student
L31: =SUM(H31:K31) -> 0
L32: =SUM(H32:K32) -> 0
L33: =SUM(H33:K33) -> 0
L34: =SUM(H34:K34) -> 0
H35: =SUM(H30:H34) -> 500 | I35: =SUM(I30:I34) -> 4500 | J35: =SUM(J30:J34) -> 3000 | K35: =SUM(K30:K34) -> 0 | L35: =SUM(L30:L34) -> 8000 | N35: =M30-L35 -> 6500 | P35: =SUM(P30:P34) -> 0
L36: =SUM(H36:K36) -> 0
L37: =SUM(H37:K37) -> 0
L38: =SUM(H38:K38) -> 0
L39: =SUM(H39:K39) -> 0
L40: =SUM(H40:K40) -> 0
...

Sheet B.Pharm I
A1: Dr.Rafiq Zakaria Campus
A2: Maulana Azad Complex of Hostel
A3: Dr.Rafiq Zakaria Marg, Rauza Bagh, Aurangabad
A4: Individual Register (B.Pharm Ist Year) for the Academic Year 2025 - 2026 'A' Wing
A5: Sr.No | B5: Name of Student & Mobile | C5: Wing & Room | D5: Class | E5: Date of Joining | F5: Receipt No. | G5: Receipt Date | H5: Regi. Fee | I5: Room Rent | J5: Water & Electricity Charges | K5: Other Activity | L5: Total Fees Collection | M5: Approved Hostel Fees | N5: Outstanding Fee | O5: Remark | P5: Security Deposit
A6: 1 | B6: Shoeb Akhtar Khuda Rahim Khan, at. Gulmohar Colony, balur road Selu, Parbhani, 9022221995, 8888151808 | D6: B.Pharm-I | F6: 7019 | G6: 10.10.2025 | H6: 500 | I6: 5000 | J6: 3000 | L6: =SUM(H6:K6) -> 8500 | M6: 17500 | P6: 1500
L7: =SUM(H7:K7) -> 0
L8: =SUM(H8:K8) -> 0
L9: =SUM(H9:K9) -> 0
L10: =SUM(H10:K10) -> 0
H11: =SUM(H6:H10) -> 500 | I11: =SUM(I6:I10) -> 5000 | J11: =SUM(J6:J10) -> 3000 | K11: =SUM(K6:K10) -> 0 | L11: =SUM(L6:L10) -> 8500 | N11: =M6-L11 -> 9000 | P11: =SUM(P6:P10) -> 1500
A12: 2 | B12: Mujammilkhan Akramkhan Pathan, at. Pirsavangi, Badnapur, Jalna, 8378050907, 9595959656 | C12: A- | D12: B.Pharm-I | F12: 7033 | G12: 31.10.2025 | H12: 500 | I12: 5000 | J12: 3000 | L12: =SUM(H12:K12) -> 8500 | M12: 17500 | P12: 1500
L13: =SUM(H13:K13) -> 0
L14: =SUM(H14:K14) -> 0
L15: =SUM(H15:K15) -> 0
L16: =SUM(H16:K16) -> 0
H17: =SUM(H12:H16) -> 500 | I17: =SUM(I12:I16) -> 5000 | J17: =SUM(J12:J16) -> 3000 | K17: =SUM(K12:K16) -> 0 | L17: =SUM(L12:L16) -> 8500 | N17: =M12-L17 -> 9000 | P17: =SUM(P12:P16) -> 1500
A18: 3 | B18: Nahid Javed Shaikh, at. Lasur Station, Tq. Gangapur, 7821852482, 9923011030 | C18: A-28 | D18: B.Pharm-I | E18: 06.11.2025 to 06.09.2026 | F18: 7044 | G18: 06.11.2025 | H18: 500 | I18: 14000 | J18: 3000 | L18: =SUM(H18:K18) -> 17500 | M18: 17500 | P18: 1500
L19: =SUM(H19:K19) -> 0
L20: =SUM(H20:K20) -> 0
L21: =SUM(H21:K21) -> 0
L22: =SUM(H22:K22) -> 0
H23: =SUM(H18:H22) -> 500 | I23: =SUM(I18:I22) -> 14000 | J23: =SUM(J18:J22) -> 3000 | K23: =SUM(K18:K22) -> 0 | L23: =SUM(L18:L22) -> 17500 | N23: =M18-L23 -> 0 | P23: =SUM(P18:P22) -> 1500
A24: 4 | B24: Rohit Ramesh Adhav, at. Sanmitra Colony, Partur, 9309789724, 7875427754 | C24: A-15 | D24: B.Pharm-I | F24: 7052 | G24: 08.11.2025 | H24: 500 | I24: 5000 | J24: 3000 | L24: =SUM(H24:K24) -> 8500 | M24: 17500 | P24: 1500
L25: =SUM(H25:K25) -> 0
L26: =SUM(H26:K26) -> 0
L27: =SUM(H27:K27) -> 0
L28: =SUM(H28:K28) -> 0
H29: =SUM(H24:H28) -> 500 | I29: =SUM(I24:I28) -> 5000 | J29: =SUM(J24:J28) -> 3000 | K29: =SUM(K24:K28) -> 0 | L29: =SUM(L24:L28) -> 8500 | N29: =M24-L29 -> 9000 | P29: =SUM(P24:P28) -> 1500
A30: 5 | B30: krushna Shantaram Sapkal, at. Near Jama Masjid, Telepura Deulghat, Buldhana, 9860284403 | D30: B.Pharm-I | F30: 7053 | G30: 08.11.2025 | H30: 500 | I30: 3000 | L30: =SUM(H30:K30) -> 3500 | M30: 17500 | P30: 1500
L31: =SUM(H31:K31) -> 0
L32: =SUM(H32:K32) -> 0
L33: =SUM(H33:K33) -> 0
L34: =SUM(H34:K34) -> 0
H35: =SUM(H30:H34) -> 500 | I35: =SUM(I30:I34) -> 3000 | J35: =SUM(J30:J34) -> 0 | K35: =SUM(K30:K34) -> 0 | L35: =SUM(L30:L34) -> 3500 | N35: =M30-L35 -> 14000 | P35: =SUM(P30:P34) -> 1500
A36: 6 | B36: Pathan Asef Abed, at. Manzari Haveli, Beed, 8783237273, 8459338682 | C36: A-25 | D36: B.Pharm-I | E36: 12.11.2025 to 12.09.2026 | F36: 7074 | G36: 12.11.2025 | H36: 500 | I36: 5000 | J36: 3000 | L36: =SUM(H36:K36) -> 8500 | M36: 17500 | P36: 1500
L37: =SUM(H37:K37) -> 0
L38: =SUM(H38:K38) -> 0
L39: =SUM(H39:K39) -> 0
L40: =SUM(H40:K40) -> 0
...

Sheet B.Pharm I (B)
A1: Dr.Rafiq Zakaria Campus
A2: Maulana Azad Complex of Hostel
A3: Dr.Rafiq Zakaria Marg, Rauza Bagh, Aurangabad
A4: Individual Register (B.Pharm Ist Year) for the Academic Year 2025 - 2026 'B' Wing
A5: Sr.No | B5: Name of Student & Mobile | C5: Wing & Room | D5: Class | E5: Date of Joining | F5: Receipt No. | G5: Receipt Date | H5: Regi. Fee | I5: Room Rent | J5: Water & Electricity Charges | K5: Other Activity | L5: Total Fees Collection | M5: Approved Hostel Fees | N5: Outstanding Fee | O5: Remark | P5: Security Deposit
L6: =SUM(H6:K6) -> 0
L7: =SUM(H7:K7) -> 0
L8: =SUM(H8:K8) -> 0
L9: =SUM(H9:K9) -> 0
L10: =SUM(H10:K10) -> 0
H11: =SUM(H6:H10) -> 0 | I11: =SUM(I6:I10) -> 0 | J11: =SUM(J6:J10) -> 0 | K11: =SUM(K6:K10) -> 0 | L11: =SUM(L6:L10) -> 0 | N11: =M6-L11 -> 0
A12: =A6+1 -> 1 | L12: =SUM(H12:K12) -> 0
L13: =SUM(H13:K13) -> 0
L14: =SUM(H14:K14) -> 0
L15: =SUM(H15:K15) -> 0
L16: =SUM(H16:K16) -> 0
F17: Total | H17: =SUM(H12:H16) -> 0 | I17: =SUM(I12:I16) -> 0 | J17: =SUM(J12:J16) -> 0 | K17: =SUM(K12:K16) -> 0 | L17: =SUM(L12:L16) -> 0 | N17: =M12-L17 -> 0 | O17: UTR | P17: =SUM(P12:P16) -> 0
A18: Total Fees Collection | H18: =+H17+H11 -> 0 | I18: =+I17+I11 -> 0 | J18: =+J17+J11 -> 0 | K18: =+K17+K11 -> 0 | L18: =+L17+L11 -> 0 | M18: =+M12+M6 -> 0 | N18: =+N17+N11 -> 0 | P18: =+P17+P11 -> 0
C22: B
C23: C
C24: D | D24: 1

Sheet B.Pharm II
A1: Dr.Rafiq Zakaria Campus
A2: Maulana Azad Complex of Hostel
A3: Dr.Rafiq Zakaria Marg, Rauza Bagh, Aurangabad
A4: Individual Register (B.Pharm IInd Year) for the Academic Year 2025 - 2026 'A' Wing
A5: Sr.No | B5: Name of Student & Mobile | C5: Wing & Room | D5: Class | E5: Date of Joining | F5: Receipt No. | G5: Receipt Date | H5: Regi. Fee | I5: Room Rent | J5: Water & Electricity Charges | K5: Other Activity | L5: Total Fees Collection | M5: Approved Hostel Fees | N5: Outstanding Fee | O5: Remark | P5: Security Deposit
A6: 1 | B6: Mohammad Abdul Raheman Mohammad Ateeque, Rahim Nagar Parbhani, 9028066310, 8329733882 | C6: A-03 | D6: B.Pharm. II | E6: 24.08.2025 to 24.06.2026 | F6: 6902 | G6: 25.08.2025 | H6: 500 | I6: 14000 | J6: 3000 | L6: =SUM(H6:K6) -> 17500 | M6: 17500 | O6: Old Sudent
L7: =SUM(H7:K7) -> 0
L8: =SUM(H8:K8) -> 0
L9: =SUM(H9:K9) -> 0
L10: =SUM(H10:K10) -> 0
H11: =SUM(H6:H10) -> 500 | I11: =SUM(I6:I10) -> 14000 | J11: =SUM(J6:J10) -> 3000 | K11: =SUM(K6:K10) -> 0 | L11: =SUM(L6:L10) -> 17500 | N11: =M6-L11 -> 0
A12: 2 | B12: Pritam Dhondiba Bhalerao, Siddharth Nagar, Taroda(BK), Nanded, 9284794287, | C12: A-24 | D12: B.Pharm. II | E12: 24.08.2025 to 24.06.2026 | F12: 6929 | G12: 09.09.2025 | H12: 500 | I12: 4000 | J12: 3000 | L12: =SUM(H12:K12) -> 7500 | M12: 17500 | O12: Old Sudent
L13: =SUM(H13:K13) -> 0
L14: =SUM(H14:K14) -> 0
L15: =SUM(H15:K15) -> 0
L16: =SUM(H16:K16) -> 0
H17: =SUM(H12:H16) -> 500 | I17: =SUM(I12:I16) -> 4000 | J17: =SUM(J12:J16) -> 3000 | K17: =SUM(K12:K16) -> 0 | L17: =SUM(L12:L16) -> 7500 | N17: =M12-L17 -> 10000
A18: 3 | B18: Momin Md Taha Md Yusuf , At .Momin Mohalla Walur, Parbhani, 7796520168,9890255186 | C18: A-01 | D18: B.Pharm. II | E18: 22.08.2025 to 22.06.2026 | F18: 6953 | G18: 12.09.2025 | H18: 500 | I18: 6500 | J18: 3000 | L18: =SUM(H18:K18) -> 10000 | M18: 17500 | O18: Old Sudent
L19: =SUM(H19:K19) -> 0
L20: =SUM(H20:K20) -> 0
L21: =SUM(H21:K21) -> 0
L22: =SUM(H22:K22) -> 0
H23: =SUM(H18:H22) -> 500 | I23: =SUM(I18:I22) -> 6500 | J23: =SUM(J18:J22) -> 3000 | K23: =SUM(K18:K22) -> 0 | L23: =SUM(L18:L22) -> 10000 | N23: =M18-L23 -> 7500
A24: 4 | B24: Faiz Shaikh Anis Pinjari, Aditya Nagar Patna Devi Road, Chalisgaon, Dist. Jalgaon, 8605188509, 9921188257 | C24: A-23 | D24: B.Pharm. II | E24: 02.09.2025 to 02.07.2026 | F24: 6952 | G24: 12.09.2025 | H24: 500 | I24: 6500 | J24: 3000 | L24: =SUM(H24:K24) -> 10000 | M24: 17500 | O24: Old Sudent
L25: =SUM(H25:K25) -> 0
L26: =SUM(H26:K26) -> 0
L27: =SUM(H27:K27) -> 0
L28: =SUM(H28:K28) -> 0
H29: =SUM(H24:H28) -> 500 | I29: =SUM(I24:I28) -> 6500 | J29: =SUM(J24:J28) -> 3000 | K29: =SUM(K24:K28) -> 0 | L29: =SUM(L24:L28) -> 10000 | N29: =M24-L29 -> 7500
A30: =A24+1 -> 5 | B30: Shaikh Muaaz Ahmed Shaikh Masood Ahmed, At. Zum Zum Colony, Beed, 9421946494, 9284711071 | C30: A-22 | D30: B.Pharm. II | E30: 05.09.2025 to 05.07.2026 | F30: 6966 | G30: 17.09.2025 | H30: 500 | I30: 6500 | J30: 3000 | L30: =SUM(H30:K30) -> 10000 | M30: 17500 | O30: Old Sudent
L31: =SUM(H31:K31) -> 0 | O31: UPI
L32: =SUM(H32:K32) -> 0
L33: =SUM(H33:K33) -> 0
L34: =SUM(H34:K34) -> 0
F35: Total | H35: =SUM(H30:H34) -> 500 | I35: =SUM(I30:I34) -> 6500 | J35: =SUM(J30:J34) -> 3000 | K35: =SUM(K30:K34) -> 0 | L35: =SUM(L30:L34) -> 10000 | N35: =M30-L35 -> 7500 | O35: UTR | P35: =SUM(P30:P34) -> 0
A36: =A30+1 -> 6 | B36: Syed Mujtaba Syed Younus, At. Mullah Masjid Gandhi Park, Parbhani,9766634222, 8055685568 | C36: A-03 | D36: B.Pharm. II | E36: 17.08.2025 to 17.06.2026 | F36: 6981 | G36: 23.09.2025 | H36: 500 | I36: 14000 | J36: 3000 | L36: =SUM(H36:K36) -> 17500 | M36: 17500 | O36: Old Sudent
L37: =SUM(H37:K37) -> 0
L38: =SUM(H38:K38) -> 0
L39: =SUM(H39:K39) -> 0
L40: =SUM(H40:K40) -> 0
...

Sheet B.Pharm II (B)
A1: Dr.Rafiq Zakaria Campus
A2: Maulana Azad Complex of Hostel
A3: Dr.Rafiq Zakaria Marg, Rauza Bagh, Aurangabad
A4: Individual Register (B.Pharm IInd Year) for the Academic Year 2025 - 2026 'A' Wing
A5: Sr.No | B5: Name of Student & Mobile | C5: Wing & Room | D5: Class | E5: Date of Joining | F5: Receipt No. | G5: Receipt Date | H5: Regi. Fee | I5: Room Rent | J5: Water & Electricity Charges | K5: Other Activity | L5: Total Fees Collection | M5: Approved Hostel Fees | N5: Outstanding Fee | O5: Remark | P5: Security Deposit
A6: 1 | B6: Fazal Yusuf Patel, at Hno33 Gendalal Mill Jalgaon, 9158415525, 9028440286 | C6: C-16 | D6: B.Pharm. II | E6: 02.09.2025 to 02.07.2026 | F6: 6919 | G6: 03.09.2025 | H6: 500 | I6: 3000 | J6: 3000 | L6: =SUM(H6:K6) -> 6500 | M6: 14500 | P6: 1500
L7: =SUM(H7:K7) -> 0
L8: =SUM(H8:K8) -> 0
L9: =SUM(H9:K9) -> 0
L10: =SUM(H10:K10) -> 0
H11: =SUM(H6:H10) -> 500 | I11: =SUM(I6:I10) -> 3000 | J11: =SUM(J6:J10) -> 3000 | K11: =SUM(K6:K10) -> 0 | L11: =SUM(L6:L10) -> 6500 | N11: =M6-L11 -> 8000 | P11: =SUM(P6:P10) -> 1500
A12: 2 | B12: Pathan Abuzar Khan Ayaz Khan, At. Kanhaiya Nagar Jalna, 9765976833,9421318948 | C12: C-27 | D12: B-Pharm II | E12: 14.09.2025 to 14.07.2026 | F12: 6968 | G12: 18.09.2025 | H12: 500 | I12: 1500 | J12: 3000 | L12: =SUM(H12:K12) -> 5000 | M12: 14500 | O12: Old Student
L13: =SUM(H13:K13) -> 0
L14: =SUM(H14:K14) -> 0
L15: =SUM(H15:K15) -> 0
L16: =SUM(H16:K16) -> 0
H17: =SUM(H12:H16) -> 500 | I17: =SUM(I12:I16) -> 1500 | J17: =SUM(J12:J16) -> 3000 | K17: =SUM(K12:K16) -> 0 | L17: =SUM(L12:L16) -> 5000 | N17: =M12-L17 -> 9500 | P17: =SUM(P12:P16) -> 0
A18: 3 | B18: Sahil Abdul Raheman Inamdar, at. Ambavane Tq. Velha, Pune, 8177874563, 7030081967 | C18: D-03 | D18: B.Pharm. II | E18: 22.09.2025 to 22.07.2026 | F18: 7018 | G18: 09.10.2025 | H18: 500 | I18: 11000 | J18: 3000 | L18: =SUM(H18:K18) -> 14500 | M18: 14500 | O18: Old Student
L19: =SUM(H19:K19) -> 0
L20: =SUM(H20:K20) -> 0
L21: =SUM(H21:K21) -> 0
L22: =SUM(H22:K22) -> 0
H23: =SUM(H18:H22) -> 500 | I23: =SUM(I18:I22) -> 11000 | J23: =SUM(J18:J22) -> 3000 | K23: =SUM(K18:K22) -> 0 | L23: =SUM(L18:L22) -> 14500 | N23: =M18-L23 -> 0 | P23: =SUM(P18:P22) -> 0
L24: =SUM(H24:K24) -> 0
L25: =SUM(H25:K25) -> 0
L26: =SUM(H26:K26) -> 0
L27: =SUM(H27:K27) -> 0
L28: =SUM(H28:K28) -> 0
H29: =SUM(H24:H28) -> 0 | I29: =SUM(I24:I28) -> 0 | J29: =SUM(J24:J28) -> 0 | K29: =SUM(K24:K28) -> 0 | L29: =SUM(L24:L28) -> 0 | N29: =M24-L29 -> 0 | P29: =SUM(P24:P28) -> 0
L30: =SUM(H30:K30) -> 0
L31: =SUM(H31:K31) -> 0
L32: =SUM(H32:K32) -> 0
L33: =SUM(H33:K33) -> 0
L34: =SUM(H34:K34) -> 0
H35: =SUM(H30:H34) -> 0 | I35: =SUM(I30:I34) -> 0 | J35: =SUM(J30:J34) -> 0 | K35: =SUM(K30:K34) -> 0 | L35: =SUM(L30:L34) -> 0 | N35: =M30-L35 -> 0 | P35: =SUM(P30:P34) -> 0
L36: =SUM(H36:K36) -> 0
L37: =SUM(H37:K37) -> 0
L38: =SUM(H38:K38) -> 0
L39: =SUM(H39:K39) -> 0
L40: =SUM(H40:K40) -> 0
...

Sheet B.Pharm III
A1: Dr.Rafiq Zakaria Campus
A2: Maulana Azad Complex of Hostel
A3: Dr.Rafiq Zakaria Marg, Rauza Bagh, Aurangabad
A4: Individual Register (B.Pharm IIIrd Year) for the Academic Year 2025 - 2026 'A' Wing
A5: Sr.No | B5: Name of Student & Mobile | C5: Wing & Room | D5: Class | E5: Date of Joining | F5: Receipt No. | G5: Receipt Date | H5: Regi. Fee | I5: Room Rent | J5: Water & Electricity Charges | K5: Other Activity | L5: Total Fees Collection | M5: Approved Hostel Fees | N5: Outstanding Fee | O5: Remark | P5: Security Deposit
A6: 1 | B6: Shaikh Aqib Azeem, at. Fardapur Tq. Soegaon, 772052073 | C6: A-29 | D6: B.Pharm-III | E6: 20.06.2025 to 20.04.2026 | F6: 6813 | G6: 19.07.2025 | H6: 500 | I6: 6500 | J6: 3000 | L6: =SUM(H6:K6) -> 10000 | M6: 17500 | O6: Old Student
L7: =SUM(H7:K7) -> 0
L8: =SUM(H8:K8) -> 0
L9: =SUM(H9:K9) -> 0
L10: =SUM(H10:K10) -> 0
H11: =SUM(H6:H10) -> 500 | I11: =SUM(I6:I10) -> 6500 | J11: =SUM(J6:J10) -> 3000 | K11: =SUM(K6:K10) -> 0 | L11: =SUM(L6:L10) -> 10000 | N11: =M6-L11 -> 7500 | R11: =1450*3 -> 4350
A12: 2 | B12: Alkama Ashokali Shaikh,At. Punatgaon, Po Pachegaon, Newasa, 9049137682 | C12: A-29 | D12: B.Pharm-III | E12: 02.07.2025 to 02.05.2026 | F12: 6814 | G12: 19.07.2025 | H12: 500 | I12: 6500 | J12: 3000 | L12: =SUM(H12:K12) -> 10000 | M12: 17500 | O12: Old Student
L13: =SUM(H13:K13) -> 0
L14: =SUM(H14:K14) -> 0
L15: =SUM(H15:K15) -> 0
L16: =SUM(H16:K16) -> 0
H17: =SUM(H12:H16) -> 500 | I17: =SUM(I12:I16) -> 6500 | J17: =SUM(J12:J16) -> 3000 | K17: =SUM(K12:K16) -> 0 | L17: =SUM(L12:L16) -> 10000 | N17: =M12-L17 -> 7500
A18: 3 | B18: Mohatsin Hasnain Yunus Shaikh At.post Ranjani, Tq. Ghansawangi, 9172158388 | C18: A-09 | D18: B.Phaarm III Year | E18: 02.06.2025 to 02.04.2026 | F18: 6837 | G18: 28.07.2025 | H18: 500 | I18: 3500 | J18: 3000 | L18: =SUM(H18:K18) -> 7000 | M18: 17500 | O18: Old Student
F19: 6903 | G19: 25.08.2025 | I19: 10500 | L19: =SUM(H19:K19) -> 10500
L20: =SUM(H20:K20) -> 0
L21: =SUM(H21:K21) -> 0
L22: =SUM(H22:K22) -> 0
H23: =SUM(H18:H22) -> 500 | I23: =SUM(I18:I22) -> 14000 | J23: =SUM(J18:J22) -> 3000 | K23: =SUM(K18:K22) -> 0 | L23: =SUM(L18:L22) -> 17500 | N23: =M18-L23 -> 0
A24: 4 | B24: Umer Nasir Deshmukh, At. Dhangar wada Yawal, Dist. Jalgaon, 9049289286 | C24: A-08 | D24: B.Pharm III Year | E24: 02.07.2025 to 02.05.2026 | F24: 6889 | G24: 21.08.2025 | H24: 500 | I24: 6500 | J24: 3000 | L24: =SUM(H24:K24) -> 10000 | M24: 17500 | O24: Old Student
L25: =SUM(H25:K25) -> 0
L26: =SUM(H26:K26) -> 0
L27: =SUM(H27:K27) -> 0
L28: =SUM(H28:K28) -> 0
H29: =SUM(H24:H28) -> 500 | I29: =SUM(I24:I28) -> 6500 | J29: =SUM(J24:J28) -> 3000 | K29: =SUM(K24:K28) -> 0 | L29: =SUM(L24:L28) -> 10000 | N29: =M24-L29 -> 7500
A30: 5 | B30: Sufiyan Rasul Shaikh, At. Post. Jahur Tq. Mukhed, 7775091710,9730690799 | C30: A-08 | D30: B.Pharm III Year | E30: 02.06.2025 to 02.04.2026 | F30: 6925 | G30: 07.09.2025 | H30: 500 | I30: 5500 | J30: 3000 | L30: =SUM(H30:K30) -> 9000 | M30: 17500 | O30: Old Student
L31: =SUM(H31:K31) -> 0
L32: =SUM(H32:K32) -> 0
L33: =SUM(H33:K33) -> 0
L34: =SUM(H34:K34) -> 0
H35: =SUM(H30:H34) -> 500 | I35: =SUM(I30:I34) -> 5500 | J35: =SUM(J30:J34) -> 3000 | K35: =SUM(K30:K34) -> 0 | L35: =SUM(L30:L34) -> 9000 | N35: =M30-L35 -> 8500
A36: 6 | B36: Adnan Ahemad Irshad Ahemad At. Kalal ki chawal Momon pura, Akola 9823269728 | C36: A-26 | D36: B.Pharm III Year | E36: 02.07.2025 to 02.05.2026 | F36: 6983 | G36: 23.09.2025 | H36: 500 | I36: 6500 | J36: 3000 | L36: =SUM(H36:K36) -> 10000 | M36: 17500 | O36: Old Student
L37: =SUM(H37:K37) -> 0
L38: =SUM(H38:K38) -> 0
L39: =SUM(H39:K39) -> 0
L40: =SUM(H40:K40) -> 0
...

Sheet B.Pharm III (B)
A1: Dr.Rafiq Zakaria Campus
A2: Maulana Azad Complex of Hostel
A3: Dr.Rafiq Zakaria Marg, Rauza Bagh, Aurangabad
A4: Individual Register (B.Pharm IIIrd Year) for the Academic Year 2025 - 2026 'B' Wing
A5: Sr.No | B5: Name of Student & Mobile | C5: Wing & Room | D5: Class | E5: Date of Joining | F5: Receipt No. | G5: Receipt Date | H5: Regi. Fee | I5: Room Rent | J5: Water & Electricity Charges | K5: Other Activity | L5: Total Fees Collection | M5: Approved Hostel Fees | N5: Outstanding Fee | O5: Remark | P5: Security Deposit
A6: 1 | B6: Vedant Rajendra Thadkar, at. Sangai Plot, Anjangaon Surji, Dist. Amravati, 7823858959, 9975258501 | C6: D-09 | D6: B.Pharm-III | E6: 27.04.2025 to 27.02.2026 | F6: 6811 | G6: 17.07.2025 | H6: 500 | I6: 4500 | J6: 3000 | L6: =SUM(H6:K6) -> 8000 | M6: 14500 | O6: Old Student
L7: =SUM(H7:K7) -> 0
L8: =SUM(H8:K8) -> 0
L9: =SUM(H9:K9) -> 0
L10: =SUM(H10:K10) -> 0
H11: =SUM(H6:H10) -> 500 | I11: =SUM(I6:I10) -> 4500 | J11: =SUM(J6:J10) -> 3000 | K11: =SUM(K6:K10) -> 0 | L11: =SUM(L6:L10) -> 8000 | N11: =M6-L11 -> 6500
A12: 2 | B12: Amaan Firoz Shaikh At.Jomala Bhokardan Dist. Jalna 9423454588, 9767931234 | C12: B-05 | D12: B.Phaarm III Year | E12: 02.07.2025 to 02.05.2026 | F12: 6867 | G12: 12.08.2025 | H12: 500 | I12: 3500 | J12: 3000 | L12: =SUM(H12:K12) -> 7000 | M12: 14500 | O12: Old Student
L13: =SUM(H13:K13) -> 0
L14: =SUM(H14:K14) -> 0
L15: =SUM(H15:K15) -> 0
L16: =SUM(H16:K16) -> 0
H17: =SUM(H12:H16) -> 500 | I17: =SUM(I12:I16) -> 3500 | J17: =SUM(J12:J16) -> 3000 | K17: =SUM(K12:K16) -> 0 | L17: =SUM(L12:L16) -> 7000 | N17: =M12-L17 -> 7500
A18: 3 | B18: Ritesh Vilasrao Deshmukh, At. Ayodhya Nagar, Hadgaon, Nanded, 9689050951,8237198571 | C18: D-09 | D18: B.Pharm III Year | E18: 02.07.2025 to 02.05.2026 | F18: 6890 | G18: 21.08.2025 | H18: 500 | I18: 11000 | J18: 3000 | L18: =SUM(H18:K18) -> 14500 | M18: 14500 | O18: Old Student
L19: =SUM(H19:K19) -> 0
L20: =SUM(H20:K20) -> 0
L21: =SUM(H21:K21) -> 0
L22: =SUM(H22:K22) -> 0
H23: =SUM(H18:H22) -> 500 | I23: =SUM(I18:I22) -> 11000 | J23: =SUM(J18:J22) -> 3000 | K23: =SUM(K18:K22) -> 0 | L23: =SUM(L18:L22) -> 14500 | N23: =M18-L23 -> 0
A24: 4 | L24: =SUM(H24:K24) -> 0
L25: =SUM(H25:K25) -> 0
L26: =SUM(H26:K26) -> 0
L27: =SUM(H27:K27) -> 0
L28: =SUM(H28:K28) -> 0
H29: =SUM(H24:H28) -> 0 | I29: =SUM(I24:I28) -> 0 | J29: =SUM(J24:J28) -> 0 | K29: =SUM(K24:K28) -> 0 | L29: =SUM(L24:L28) -> 0 | N29: =M24-L29 -> 0
A30: 5 | L30: =SUM(H30:K30) -> 0
L31: =SUM(H31:K31) -> 0
L32: =SUM(H32:K32) -> 0
L33: =SUM(H33:K33) -> 0
L34: =SUM(H34:K34) -> 0
H35: =SUM(H30:H34) -> 0 | I35: =SUM(I30:I34) -> 0 | J35: =SUM(J30:J34) -> 0 | K35: =SUM(K30:K34) -> 0 | L35: =SUM(L30:L34) -> 0 | N35: =M30-L35 -> 0
A36: 6 | L36: =SUM(H36:K36) -> 0
L37: =SUM(H37:K37) -> 0
L38: =SUM(H38:K38) -> 0
L39: =SUM(H39:K39) -> 0
L40: =SUM(H40:K40) -> 0
...

Sheet B.Pharm IV
A1: Dr.Rafiq Zakaria Campus
A2: Maulana Azad Complex of Hostel
A3: Dr.Rafiq Zakaria Marg, Rauza Bagh, Aurangabad
A4: Individual Register (B.Pharm IVth Year) for the Academic Year 2025 - 2026 'A' Wing
A5: Sr.No | B5: Name of Student & Mobile | C5: Wing & Room | D5: Class | E5: Date of Joining | F5: Receipt No. | G5: Receipt Date | H5: Regi. Fee | I5: Room Rent | J5: Water & Electricity Charges | K5: Other Activity | L5: Total Fees Collection | M5: Approved Hostel Fees | N5: Outstanding Fee | O5: Remark | P5: Security Deposit
A6: 1 | B6: Sarang Vilas Salunke,at. Shangavi Residensy C-08, New Court, Baramati, 9499465146, 7058372405 | C6: A-25 | D6: B.Pharm-IV | E6: 23.04.2025 to 23.02.2026 | F6: 6696 | G6: 17.06.2025 | H6: 500 | I6: 14000 | J6: 3000 | L6: =SUM(H6:K6) -> 17500 | M6: 17500 | O6: UPI
L7: =SUM(H7:K7) -> 0 | O7: Old Student
L8: =SUM(H8:K8) -> 0
L9: =SUM(H9:K9) -> 0
L10: =SUM(H10:K10) -> 0
L11: =SUM(L6:L10) -> 17500 | N11: =M6-L11 -> 0 | P11: =SUM(P6:P10) -> 0
A12: 2 | B12: Shaikh Faizan Shaikh Hamid, at. Anturli Tq. Muktainagar, Dist. Jalgaon, 9765146095, 9272938202 | C12: A-19 | D12: B.Pharm-IV | E12: 11.05.2025 to 11.03.2026 | F12: 6773 | G12: 08.07.2025 | H12: 500 | I12: 4000 | J12: 3000 | L12: =SUM(H12:K12) -> 7500 | M12: 17500 | O12: Old Student
L13: =SUM(H13:K13) -> 0
L14: =SUM(H14:K14) -> 0
L15: =SUM(H15:K15) -> 0
L16: =SUM(H16:K16) -> 0
H17: =SUM(H12:H16) -> 500 | I17: =SUM(I12:I16) -> 4000 | J17: =SUM(J12:J16) -> 3000 | K17: =SUM(K12:K16) -> 0 | L17: =SUM(L12:L16) -> 7500 | N17: =M12-L17 -> 10000 | P17: =SUM(P12:P16) -> 0
A18: 3 | B18: Shaikh Sameer Mainoddin, At. Usmanpura Colony, Sanja Road Osmanabad, 9922595756, 9767192430 | C18: A-09 | D18: B.Pharm-IV | E18: 13.05.2025 to 13.03.2026 | F18: 6780 | G18: 10.07.2025 | H18: 500 | I18: 6500 | J18: 3000 | L18: =SUM(H18:K18) -> 10000 | M18: 17500 | O18: Old Student
L19: =SUM(H19:K19) -> 0
L20: =SUM(H20:K20) -> 0
L21: =SUM(H21:K21) -> 0
L22: =SUM(H22:K22) -> 0
H23: =SUM(H18:H22) -> 500 | I23: =SUM(I18:I22) -> 6500 | J23: =SUM(J18:J22) -> 3000 | K23: =SUM(K18:K22) -> 0 | L23: =SUM(L18:L22) -> 10000 | N23: =M18-L23 -> 7500 | P23: =SUM(P18:P22) -> 0
A24: 4 | B24: Shaikh Afroz Sayeed, at. Chandanzira, Jalna, 9890454350, 9075876345 | C24: A-19 | D24: B.Pharm-IV | E24: 13.05.2025 to 13.03.2026 | F24: 6785 | G24: 11.07.2025 | H24: 500 | I24: 6500 | J24: 3000 | L24: =SUM(H24:K24) -> 10000 | M24: 17500 | O24: Old Student
F25: c | L25: =SUM(H25:K25) -> 0
L26: =SUM(H26:K26) -> 0
L27: =SUM(H27:K27) -> 0
L28: =SUM(H28:K28) -> 0
H29: =SUM(H24:H28) -> 500 | I29: =SUM(I24:I28) -> 6500 | J29: =SUM(J24:J28) -> 3000 | K29: =SUM(K24:K28) -> 0 | L29: =SUM(L24:L28) -> 10000 | N29: =M24-L29 -> 7500 | P29: =SUM(P24:P28) -> 0
A30: 5 | B30: Ikkar Mahadev Baburao Sujata Colony old Pedgaon Road, Dist.Parbhani 8010625321, 8080277913 | C30: A-27 | D30: B.Pharm-IV | E30: 02.07.2025 to 02.05.2026 | F30: 6798 | G30: 16.07.2025 | H30: 500 | I30: 5000 | J30: 3000 | L30: =SUM(H30:K30) -> 8500 | M30: 17500 | O30: Old Student
F31: 7031 | G31: 30.10.2025 | I31: 9000 | L31: =SUM(H31:K31) -> 9000
L32: =SUM(H32:K32) -> 0
L33: =SUM(H33:K33) -> 0
L34: =SUM(H34:K34) -> 0
H35: =SUM(H30:H34) -> 500 | I35: =SUM(I30:I34) -> 14000 | J35: =SUM(J30:J34) -> 3000 | K35: =SUM(K30:K34) -> 0 | L35: =SUM(L30:L34) -> 17500 | N35: =M30-L35 -> 0 | P35: =SUM(P30:P34) -> 0
A36: 6 | B36: Shivam Dnyaneshwar Rangdal, 227, Shrishal Nagar bhavani peth, Solapur, 8668866179,9834718107 | C36: A-27 | D36: B.Pharm-IV | E36: 02.07.2025 to 02.05.2026 | F36: 6799 | G36: 16.07.2025 | H36: 500 | I36: 5000 | J36: 3000 | L36: =SUM(H36:K36) -> 8500 | M36: 17500 | O36: Old Student
F37: 7007 | G37: 06.10.2025 | I37: 3500 | L37: =SUM(H37:K37) -> 3500
L38: =SUM(H38:K38) -> 0
L39: =SUM(H39:K39) -> 0
L40: =SUM(H40:K40) -> 0
...

Sheet B.Pharm IV (B)
A1: Dr.Rafiq Zakaria Campus
A2: Maulana Azad Complex of Hostel
A3: Dr.Rafiq Zakaria Marg, Rauza Bagh, Aurangabad
A4: Individual Register (B.Pharm IVth Year) for the Academic Year 2025 - 2026 'C' Wing
A5: Sr.No | B5: Name of Student & Mobile | C5: Wing & Room | D5: Class | E5: Date of Joining | F5: Receipt No. | G5: Receipt Date | H5: Regi. Fee | I5: Room Rent | J5: Water & Electricity Charges | K5: Other Activity | L5: Total Fees Collection | M5: Approved Hostel Fees | N5: Outstanding Fee | O5: Remark | P5: Security Deposit
A6: 1 | B6: Shaikh Muzammil Faisal Umar Teachers colony Paratwada Achalpur Dist. Amravati 9028173992, 9552871992 | C6: C-32 | D6: B.Pharm IVYear | E6: 02.07.2025 to 02.05.2026 | F6: 6815 | G6: 19.07.2025 | H6: 500 | I6: 2500 | J6: 3000 | L6: =SUM(H6:K6) -> 6000 | M6: 14500
F7: 6973 | G7: 19.09.2025 | I7: 8500 | L7: =SUM(H7:K7) -> 8500
L8: =SUM(H8:K8) -> 0
L9: =SUM(H9:K9) -> 0
L10: =SUM(H10:K10) -> 0
F11: Total | H11: =SUM(H6:H10) -> 500 | I11: =SUM(I6:I10) -> 11000 | J11: =SUM(J6:J10) -> 3000 | K11: =SUM(K6:K10) -> 0 | L11: =SUM(L6:L10) -> 14500 | N11: =M6-L11 -> 0 | P11: =SUM(P6:P10) -> 0
A12: =A6+1 -> 2 | B12: Bhushan Ramkrushna Patil, At Post. Talnji, Tq Mantha Dist. Jalna, 7776040931 | C12: D-08 | D12: B.Pharm IV Year | E12: 15.09.2025 to 15.07.2026 | F12: 6894 | G12: 22.08.2025 | H12: 500 | I12: 4000 | J12: 3000 | L12: =SUM(H12:K12) -> 7500 | M12: 14500 | O12: Old Student
L13: =SUM(H13:K13) -> 0 | O13: UPI
L14: =SUM(H14:K14) -> 0
L15: =SUM(H15:K15) -> 0
L16: =SUM(H16:K16) -> 0
F17: Total | H17: =SUM(H12:H16) -> 500 | I17: =SUM(I12:I16) -> 4000 | J17: =SUM(J12:J16) -> 3000 | K17: =SUM(K12:K16) -> 0 | L17: =SUM(L12:L16) -> 7500 | N17: =M12-L17 -> 7000 | P17: =SUM(P12:P16) -> 0
A18: 3 | B18: Qureshi Ajaz Moin, At. Kalamnoori Dist. Hingoli, 9665819550 | C18: C-23 | D18: B.Pharm IV Year | E18: 02.08.2025 to 02.06.2026 | F18: 6895 | G18: 22.08.2025 | H18: 500 | I18: 3500 | J18: 3000 | L18: =SUM(H18:K18) -> 7000 | M18: 14500 | O18: Old Student
L19: =SUM(H19:K19) -> 0 | O19: UPI
L20: =SUM(H20:K20) -> 0
L21: =SUM(H21:K21) -> 0
L22: =SUM(H22:K22) -> 0
F23: Total | H23: =SUM(H18:H22) -> 500 | I23: =SUM(I18:I22) -> 3500 | J23: =SUM(J18:J22) -> 3000 | K23: =SUM(K18:K22) -> 0 | L23: =SUM(L18:L22) -> 7000 | N23: =M18-L23 -> 7500 | P23: =SUM(P18:P22) -> 0
A24: 4 | B24: Mohd Arfat L. Shivani, At. Habib Nagar Paratwada, Achalpur, dist Amrawati, 9822020782 | C24: C-34 | D24: B.Pharm IV Year | E24: 25.06.2025 to 25.04.2026 | F24: 6822 | G24: 03.09.2025 | H24: 500 | I24: 11000 | J24: 3000 | L24: =SUM(H24:K24) -> 14500 | M24: 14500 | O24: Old Student
L25: =SUM(H25:K25) -> 0 | O25: UPI
L26: =SUM(H26:K26) -> 0
L27: =SUM(H27:K27) -> 0
L28: =SUM(H28:K28) -> 0
F29: Total | H29: =SUM(H24:H28) -> 500 | I29: =SUM(I24:I28) -> 11000 | J29: =SUM(J24:J28) -> 3000 | K29: =SUM(K24:K28) -> 0 | L29: =SUM(L24:L28) -> 14500 | N29: =M24-L29 -> 0 | P29: =SUM(P24:P28) -> 0
A30: 5 | B30: Patil Kunal Jibhau Shriram 101 Nirman Shrusti Apt Uarse Raha Raigarh 7276883819, 9420810236 | C30: D-06 | D30: B.Pharm IV Year | E30: 02.09.2025 to 02.07.2026 | F30: 6972 | G30: 19.09.2025 | H30: 500 | I30: 6500 | J30: 3000 | L30: =SUM(H30:K30) -> 10000 | M30: 14500 | O30: Old Student
L31: =SUM(H31:K31) -> 0
L32: =SUM(H32:K32) -> 0
L33: =SUM(H33:K33) -> 0
L34: =SUM(H34:K34) -> 0
F35: Total | H35: =SUM(H30:H34) -> 500 | I35: =SUM(I30:I34) -> 6500 | J35: =SUM(J30:J34) -> 3000 | K35: =SUM(K30:K34) -> 0 | L35: =SUM(L30:L34) -> 10000 | N35: =M30-L35 -> 4500 | P35: =SUM(P30:P34) -> 0
A36: 6 | B36: Shaikh Moin Adam Namdarbhai At. Post. Ghogargaon Tq. Shrigonda Dist. Ahmednagar 9623395075, 9405830236 | C36: C-32 | D36: B.Pharm IV Year | E36: 02.09.2025 to 01.07.2026 | F36: 7000 | G36: 03.10.2025 | H36: 500 | I36: 11000 | J36: 3000 | L36: =SUM(H36:K36) -> 14500 | M36: 14500 | O36: Old Student
L37: =SUM(H37:K37) -> 0
L38: =SUM(H38:K38) -> 0
L39: =SUM(H39:K39) -> 0
L40: =SUM(H40:K40) -> 0
...

Sheet Summary
A1: Dr.Rafiq Zakaria Campus
A2: Maulana Azad Complex of Hostel
A3: Dr.Rafiq Zakaria Marg, Rauza Bagh, Aurangabad
A4: Summary of New Admission for 2025- 2026 Fees Collection
A6: Sr.No | B6: Name of Course | C6: Wing | D6: Admited Students | E6: Approved Fees | F6: Total Fees | G6: Fees Received | H6: Fees Outstanding
A7: 1 | B7: XI / XII / B.com / BBA /B.Sc / BCA | C7: General A | D7: 13 | E7: 17500 | F7: =+'Genera A'!M102 -> 210000 | G7: =+'Genera A'!L102 -> 135000 | H7: =+F7-G7 -> 75000
A8: 2 | B8: XI / XII / B.com / BBA /B.Sc / BCA | C8: General B | D8: 79 | E8: 14500 | F8: =+'Individual Register 2025-2026'!M498 -> 1125700 | G8: =+'Individual Register 2025-2026'!L498 -> 801000 | H8: =+F8-G8 -> 324700
A9: 3 | B9: D.Pharmacy | C9: A | D9: 0 | E9: 17500 | F9: =+'D.Pharm (A)'!M18 -> 0 | G9: =+'D.Pharm (A)'!L18 -> 0 | H9: =+F9-G9 -> 0
A10: 4 | B10: D.Pharmacy | C10: B | D10: 5 | E10: 14500 | F10: =+'D.Pharm (B)'!M54 -> 72500 | G10: =+'D.Pharm (B)'!L54 -> 45000 | H10: =+F10-G10 -> 27500
A11: 5 | B11: B.Pharm I Year | C11: A | D11: 6 | E11: 17500 | F11: =+'B.Pharm I'!M60 -> 122500 | G11: =+'B.Pharm I'!L60 -> 63500 | H11: =+F11-G11 -> 59000
A12: 6 | B12: B.Pharm I Year | C12: B | D12: 0 | E12: 14500 | F12: =+'B.Pharm I (B)'!M18 -> 0 | G12: =+'B.Pharm I (B)'!L18 -> 0 | H12: =+F12-G12 -> 0
A13: 7 | B13: B.Pharm II Year | C13: A | D13: 15 | E13: 17500 | F13: =+'B.Pharm II'!M114 -> 262500 | G13: =+'B.Pharm II'!L114 -> 180000 | H13: =+F13-G13 -> 82500
A14: 8 | B14: B.Pharm II Year | C14: B | D14: 3 | E14: 14500 | F14: =+'B.Pharm II (B)'!M49 -> 43500 | G14: =+'B.Pharm II (B)'!L49 -> 26000 | H14: =+F14-G14 -> 17500
A15: 9 | B15: B.Pharm III Year | C15: A | D15: 8 | E15: 17500 | F15: =+'B.Pharm III'!M109 -> 140000 | G15: =+'B.Pharm III'!L109 -> 94000 | H15: =+F15-G15 -> 46000
A16: 10 | B16: B.Pharm III Year | C16: B | D16: 3 | E16: 14500 | F16: =+'B.Pharm III (B)'!M60 -> 43500 | G16: =+'B.Pharm III (B)'!L60 -> 29500 | H16: =+'B.Pharm III (B)'!N60 -> 14000
A17: 11 | B17: B.Pharm IV Year | C17: A | D17: 19 | E17: 17500 | F17: =+'B.Pharm IV'!M127 -> 332500 | G17: =+'B.Pharm IV'!L127 -> 223000 | H17: =+F17-G17 -> 109500
A18: 12 | B18: B.Pharm IV Year | C18: B | D18: 6 | E18: 14500 | F18: =+'B.Pharm IV (B)'!M48 -> 87000 | G18: =+'B.Pharm IV (B)'!L48 -> 68000 | H18: =+F18-G18 -> 19000
A19: 13 | B19: M.Pharm I & II Year | C19: A | D19: 10 | E19: 17500 | F19: =+'M.Pharm I & II'!M79 -> 192500 | G19: =+'M.Pharm I & II'!L79 -> 101500 | H19: =+F19-G19 -> 91000
A20: 14 | B20: M.Pharm I & II Year | C20: B | D20: 2 | E20: 14500 | F20: =+'M.Pharm I & II (B)'!M42 -> 29000 | G20: =+'M.Pharm I & II (B)'!L42 -> 18000 | H20: =+F20-G20 -> 11000
A21: 15 | B21: B.Ed I & II Year | C21: A | D21: 1 | E21: 17500 | F21: =+'B.Ed I & II'!M36 -> 17500 | G21: =+'B.Ed I & II'!L36 -> 5000 | H21: =+F21-G21 -> 12500
A22: 16 | B22: B.Ed I & II Year | C22: B | D22: 16 | E22: 14500 | F22: =+'B.Ed I & II (B)'!M109 -> 232000 | G22: =+'B.Ed I & II (B)'!L109 -> 155500 | H22: =+F22-G22 -> 76500
A23: 17 | B23: M.Sc I & II Year | C23: A | D23: 1 | E23: 17500 | F23: =+'M.Sc I & II '!M30 -> 17500 | G23: =+'M.Sc I & II '!L30 -> 17500 | H23: =+F23-G23 -> 0
A24: 18 | B24: M.Sc I & II Year | C24: B | D24: 2 | E24: 14500 | F24: =+'M.Sc I & II (B)'!M30 -> 16000 | G24: =+'M.Sc I & II (B)'!L30 -> 7000 | H24: =+F24-G24 -> 9000
A25: 19 | B25: Temporary Admission | D25: 118 | E25: 0 | F25: =+'Temporary Adm'!J740 -> 121750 | G25: =+'Temporary Adm'!I740 -> 118450 | H25: =+F25-G25 -> 3300
A26: Total | D26: =SUM(D7:D25) -> 307 | F26: =SUM(F7:F25) -> 3065950 | G26: =SUM(G7:G25) -> 2087950 | H26: =SUM(H7:H25) -> 978000
D27: =+D26-D25 -> 189
G28: ₹ | H28: 2284950 | I28: 27.09.2025
B29: C | C29: 0 | E29: Y.B. | F29: =+D11+D12+D13+D14+D15+D16++D17+D18+D19+D20 -> 72
B30: D | C30: 0 | E30: MACA | F30: =+D7+D8+D23+D24 -> 95 | G30: ₹
B31: B | C31: 1 | E31: MCE | F31: =+D21+D22 -> 17
B32: A | C32: 0 | E32: KNPP | F32: =+D9+D10 -> 5
C33: =SUM(C29:C32) -> 1 | F33: =SUM(F29:F32) -> 189

Sheet M.Pharm I & II
A1: Dr.Rafiq Zakaria Campus
A2: Maulana Azad Complex of Hostel
A3: Dr.Rafiq Zakaria Marg, Rauza Bagh, Aurangabad
A4: Individual Register (M.Pharm I & II Year) for the Academic Year 2025 - 2026 'A' Wing
A5: Sr.No | B5: Name of Student & Mobile | C5: Wing & Room | D5: Class | E5: Date of Joining | F5: Receipt No. | G5: Receipt Date | H5: Regi. Fee | I5: Room Rent | J5: Water & Electricity Charges | K5: Other Activity | L5: Total Fees Collection | M5: Approved Hostel Fees | N5: Outstanding Fee | O5: Remark | P5: Security Deposit
A6: 1 | B6: Khatib M. Umair Azharuddin, Partur Dist. Jalna, 9309770313 | C6: A-21 | D6: M.Pharm II Year | E6: 01.07.2025 to 01.05.2026 | F6: 6744 | G6: 28.06.2025 | H6: 500 | I6: 6500 | J6: 3000 | L6: =SUM(H6:K6) -> 10000 | M6: 17500 | O6: Old Student
L7: =SUM(H7:K7) -> 0 | O7: UPI
L8: =SUM(H8:K8) -> 0
L9: =SUM(H9:K9) -> 0
L10: =SUM(H10:K10) -> 0
H11: =SUM(H6:H10) -> 500 | I11: =SUM(I6:I10) -> 6500 | J11: =SUM(J6:J10) -> 3000 | K11: =SUM(K6:K10) -> 0 | L11: =SUM(L6:L10) -> 10000 | N11: =M6-L11 -> 7500 | P11: =SUM(P6:P10) -> 0
A12: 2 | B12: Ansari yousha Ali Nasir, At. 51 Ansari Manzil Mehboob Compound RaushanBagh, Bhiwandi, 9021175730 | C12: A-21 | D12: M.Pharm II Year | E12: 01.07.2025 to 01.05.2026 | F12: 6745 | G12: 28.06.2025 | H12: 500 | I12: 6500 | J12: 3000 | L12: =SUM(H12:K12) -> 10000 | M12: 17500 | O12: Old Student
L13: =SUM(H13:K13) -> 0 | O13: UPI
L14: =SUM(H14:K14) -> 0
L15: =SUM(H15:K15) -> 0
L16: =SUM(H16:K16) -> 0
H17: =SUM(H12:H16) -> 500 | I17: =SUM(I12:I16) -> 6500 | J17: =SUM(J12:J16) -> 3000 | K17: =SUM(K12:K16) -> 0 | L17: =SUM(L12:L16) -> 10000 | M17: 17500 | N17: =M12-L17 -> 7500 | P17: =SUM(P12:P16) -> 0
A18: 3 | B18: Shaikh Muzammil Baba Siddarth Nager Ambajogai, Beed, 9552609917, 8446599689 | C18: A-20 | D18: M.Pharm II Year | E18: 17.08.2025 to 16.06.2026 | F18: 6979 | G18: 22.09.2025 | H18: 500 | I18: 14000 | J18: 3000 | L18: =SUM(H18:K18) -> 17500 | M18: 17500 | O18: Old Student
L19: =SUM(H19:K19) -> 0
L20: =SUM(H20:K20) -> 0
L21: =SUM(H21:K21) -> 0
L22: =SUM(H22:K22) -> 0
H23: =SUM(H18:H22) -> 500 | I23: =SUM(I18:I22) -> 14000 | J23: =SUM(J18:J22) -> 3000 | K23: =SUM(K18:K22) -> 0 | L23: =SUM(L18:L22) -> 17500 | N23: =M18-L23 -> 0 | P23: =SUM(P18:P22) -> 0
A24: 4 | B24: Mohammad Adnan Danish, at. Khaja Colony, Sai Nagar, Nanded, 8983555990, 7020439752 | C24: A-03 | D24: M.Pharm II Year | E24: 22.09.2025 to 22.07.2025 | F24: 7011 | G24: 07.10.2025 | H24: 500 | I24: 1500 | J24: 3000 | L24: =SUM(H24:K24) -> 5000 | M24: 17500 | O24: Old Student
L25: =SUM(H25:K25) -> 0
L26: =SUM(H26:K26) -> 0
L27: =SUM(H27:K27) -> 0
L28: =SUM(H28:K28) -> 0
H29: =SUM(H24:H28) -> 500 | I29: =SUM(I24:I28) -> 1500 | J29: =SUM(J24:J28) -> 3000 | K29: =SUM(K24:K28) -> 0 | L29: =SUM(L24:L28) -> 5000 | N29: =M24-L29 -> 12500 | P29: =SUM(P24:P28) -> 0
A30: 5 | B30: Syed Ahetashamoddin Syed Zainulabedin, at khidkipura Pimpalgaon Raja, tq Khamgaon, Buldhana, 7350750068,9145606160 | C30: A-17 | D30: M.Pharm II Year | E30: 01.09.2025 to 01.07.2026 | F30: 7022 | G30: 13.10.2025 | H30: 500 | I30: 4000 | L30: =SUM(H30:K30) -> 4500 | M30: 17500 | O30: Old Student
F31: 7034 | G31: 03.11.2025 | I31: 4500 | J31: 3000 | L31: =SUM(H31:K31) -> 7500
L32: =SUM(H32:K32) -> 0
L33: =SUM(H33:K33) -> 0
L34: =SUM(H34:K34) -> 0
H35: =SUM(H30:H34) -> 500 | I35: =SUM(I30:I34) -> 8500 | J35: =SUM(J30:J34) -> 3000 | K35: =SUM(K30:K34) -> 0 | L35: =SUM(L30:L34) -> 12000 | N35: =M30-L35 -> 5500 | P35: =SUM(P30:P34) -> 0
A36: 6 | B36: Khan Adnan Ejaz Khan, at Barkat nagar, Parli, Beed. 9529267100, 7796368686 | C36: A-17 | D36: M.Pharm II Year | E36: 08.10.2025 to 08.08.2026 | F36: 7024 | G36: 15.10.2025 | H36: 500 | I36: 3000 | L36: =SUM(H36:K36) -> 3500 | M36: 17500 | P36: 1500
L37: =SUM(H37:K37) -> 0
L38: =SUM(H38:K38) -> 0
L39: =SUM(H39:K39) -> 0
L40: =SUM(H40:K40) -> 0
...

Sheet M.Pharm I & II (B)
A1: Dr.Rafiq Zakaria Campus
A2: Maulana Azad Complex of Hostel
A3: Dr.Rafiq Zakaria Marg, Rauza Bagh, Aurangabad
A4: Individual Register (M.Pharm I & II Year) for the Academic Year 2025 - 2026 'B' Wing
A5: Sr.No | B5: Name of Student & Mobile | C5: Wing & Room | D5: Class | E5: Date of Joining | F5: Receipt No. | G5: Receipt Date | H5: Regi. Fee | I5: Room Rent | J5: Water & Electricity Charges | K5: Other Activity | L5: Total Fees Collection | M5: Approved Hostel Fees | N5: Outstanding Fee | O5: Remark | P5: Security Deposit
A6: 1 | B6: Dalvi Amit Purushottam, at.Dwarka Nagri, Akola, 8788356746, 9370400442 | C6: C-03 | D6: M.Pharm-I | E6: 01.06.2025 to 01.10.2026 | F6: 6718 | G6: 19.05.2025 | H6: 500 | I6: 1500 | J6: 3000 | L6: =SUM(H6:K6) -> 5000 | M6: 14500 | P6: 1500
F7: 6820 | G7: 22.07.2025 | I7: 9500 | L7: =SUM(H7:K7) -> 9500
L8: =SUM(H8:K8) -> 0
L9: =SUM(H9:K9) -> 0
L10: =SUM(H10:K10) -> 0
H11: =SUM(H6:H10) -> 500 | I11: =SUM(I6:I10) -> 11000 | J11: =SUM(J6:J10) -> 3000 | K11: =SUM(K6:K10) -> 0 | L11: =SUM(L6:L10) -> 14500 | N11: =+M6-L11 -> 0 | P11: =SUM(P6:P10) -> 1500
A12: 2 | B12: Suraj Gunvant Kokare, at. Pusda, Amravati, 9921350863, 7350184413 | C12: D-06 | D12: M.Pharm-I | F12: 7010 | G12: 06.10.2025 | H12: 500 | I12: 3000 | L12: =SUM(H12:K12) -> 3500 | M12: 14500 | P12: 1500
L13: =SUM(H13:K13) -> 0 | O13: UPI
L14: =SUM(H14:K14) -> 0
L15: =SUM(H15:K15) -> 0
L16: =SUM(H16:K16) -> 0
H17: =SUM(H12:H16) -> 500 | I17: =SUM(I12:I16) -> 3000 | J17: =SUM(J12:J16) -> 0 | K17: =SUM(K12:K16) -> 0 | L17: =SUM(L12:L16) -> 3500 | N17: =M12-L17 -> 11000 | P17: =SUM(P12:P16) -> 1500
A18: 3 | L18: =SUM(H18:K18) -> 0 | O18: Old Student
L19: =SUM(H19:K19) -> 0
L20: =SUM(H20:K20) -> 0
L21: =SUM(H21:K21) -> 0
L22: =SUM(H22:K22) -> 0
H23: =SUM(H18:H22) -> 0 | I23: =SUM(I18:I22) -> 0 | J23: =SUM(J18:J22) -> 0 | K23: =SUM(K18:K22) -> 0 | L23: =SUM(L18:L22) -> 0 | N23: =M18-L23 -> 0 | P23: =SUM(P18:P22) -> 0
L24: =SUM(H24:K24) -> 0
L25: =SUM(H25:K25) -> 0
L26: =SUM(H26:K26) -> 0
L27: =SUM(H27:K27) -> 0
L28: =SUM(H28:K28) -> 0
H29: =SUM(H24:H28) -> 0 | I29: =SUM(I24:I28) -> 0 | J29: =SUM(J24:J28) -> 0 | K29: =SUM(K24:K28) -> 0 | L29: =SUM(L24:L28) -> 0 | N29: =M24-L29 -> 0
L30: =SUM(H30:K30) -> 0
L31: =SUM(H31:K31) -> 0
L32: =SUM(H32:K32) -> 0
L33: =SUM(H33:K33) -> 0
L34: =SUM(H34:K34) -> 0
H35: =SUM(H30:H34) -> 0 | I35: =SUM(I30:I34) -> 0 | J35: =SUM(J30:J34) -> 0 | K35: =SUM(K30:K34) -> 0 | L35: =SUM(L30:L34) -> 0 | N35: =M30-L35 -> 0
L36: =SUM(H36:K36) -> 0
L37: =SUM(H37:K37) -> 0
L38: =SUM(H38:K38) -> 0
L39: =SUM(H39:K39) -> 0
L40: =SUM(H40:K40) -> 0
...

Sheet B.Ed I & II
A1: Dr.Rafiq Zakaria Campus
A2: Maulana Azad Complex of Hostel
A3: Dr.Rafiq Zakaria Marg, Rauza Bagh, Aurangabad
A4: Individual Register (B.ED I & II Year) for the Academic Year 2025 - 2026 'A' Wing
A5: Sr.No | B5: Name of Student & Mobile | C5: Wing & Room | D5: Class | E5: Date of Joining | F5: Receipt No. | G5: Receipt Date | H5: Regi. Fee | I5: Room Rent | J5: Water & Electricity Charges | K5: Other Activity | L5: Total Fees Collection | M5: Approved Hostel Fees | N5: Outstanding Fee | O5: Remark | P5: Security Deposit
A6: 1 | B6: Mohd. Usama Siddiqui, at. Haki Colony Dewalgaon Raja, Dist. Buldhana, 8180054260, 9860438925 | C6: A-07 | D6: B.ed II Year | E6: 01.10.2025 to 01.08.2026 | F6: 7068 | G6: 11.11.2025 | H6: 500 | I6: 1500 | J6: 3000 | L6: =SUM(H6:K6) -> 5000 | M6: 17500 | O6: Old Student
L7: =SUM(H7:K7) -> 0
L8: =SUM(H8:K8) -> 0
L9: =SUM(H9:K9) -> 0
L10: =SUM(H10:K10) -> 0
H11: =SUM(H6:H10) -> 500 | I11: =SUM(I6:I10) -> 1500 | J11: =SUM(J6:J10) -> 3000 | K11: =SUM(K6:K10) -> 0 | L11: =SUM(L6:L10) -> 5000 | N11: =M6-L11 -> 12500 | P11: =SUM(P6:P10) -> 0
L12: =SUM(H12:K12) -> 0
L13: =SUM(H13:K13) -> 0
L14: =SUM(H14:K14) -> 0
L15: =SUM(H15:K15) -> 0
L16: =SUM(H16:K16) -> 0
H17: =SUM(H12:H16) -> 0 | I17: =SUM(I12:I16) -> 0 | J17: =SUM(J12:J16) -> 0 | K17: =SUM(K12:K16) -> 0 | L17: =SUM(L12:L16) -> 0 | N17: =M12-L17 -> 0
L18: =SUM(H18:K18) -> 0
L19: =SUM(H19:K19) -> 0
L20: =SUM(H20:K20) -> 0
L21: =SUM(H21:K21) -> 0
L22: =SUM(H22:K22) -> 0
H23: =SUM(H18:H22) -> 0 | I23: =SUM(I18:I22) -> 0 | J23: =SUM(J18:J22) -> 0 | K23: =SUM(K18:K22) -> 0 | L23: =SUM(L18:L22) -> 0 | N23: =M18-L23 -> 0
L24: =SUM(H24:K24) -> 0
L25: =SUM(H25:K25) -> 0
L26: =SUM(H26:K26) -> 0
L27: =SUM(H27:K27) -> 0
L28: =SUM(H28:K28) -> 0
H29: =SUM(H24:H28) -> 0 | I29: =SUM(I24:I28) -> 0 | J29: =SUM(J24:J28) -> 0 | K29: =SUM(K24:K28) -> 0 | L29: =SUM(L24:L28) -> 0 | N29: =M24-L29 -> 0
L30: =SUM(H30:K30) -> 0
L31: =SUM(H31:K31) -> 0
L32: =SUM(H32:K32) -> 0
L33: =SUM(H33:K33) -> 0
L34: =SUM(H34:K34) -> 0
H35: =SUM(H30:H34) -> 0 | I35: =SUM(I30:I34) -> 0 | J35: =SUM(J30:J34) -> 0 | K35: =SUM(K30:K34) -> 0 | L35: =SUM(L30:L34) -> 0 | N35: =M30-L35 -> 0
A36: Total Fees Collection | H36: =+H35+H29+H23+H17+H11 -> 500 | I36: =+I35+I29+I23+I17+I11 -> 1500 | J36: =+J35+J29+J23+J17+J11 -> 3000 | K36: =+K35+K29+K23+K17+K11 -> 0 | L36: =+L35+L29+L23+L17+L11 -> 5000 | M36: =+M30+M24+M18+M12+M6 -> 17500 | N36: =+N35+N29+N23+N17+N11 -> 12500 | P36: =+P35+P29+P23+P17+P11 -> 0
A38: NOTE:

Sheet B.Ed I & II (B)
A1: Dr.Rafiq Zakaria Campus
A2: Maulana Azad Complex of Hostel
A3: Dr.Rafiq Zakaria Marg, Rauza Bagh, Aurangabad
A4: Individual Register (B.ED I & II Year) for the Academic Year 2025 - 2026 'B & C' Wing
A5: Sr.No | B5: Name of Student & Mobile | C5: Wing & Room | D5: Class | E5: Date of Joining | F5: Receipt No. | G5: Receipt Date | H5: Regi. Fee | I5: Room Rent | J5: Water & Electricity Charges | K5: Other Activity | L5: Total Fees Collection | M5: Approved Hostel Fees | N5: Outstanding Fee | O5: Remark | P5: Security Deposit
A6: 1 | B6: Shaikh Naved Shaikh Quasim, at. Tilak Nagar, Chikli Dist.Buldhana, 9595337725 | C6: C-22 | D6: B.ed.II | E6: 19.06.2025 to 19.04.2026 | F6: 6735 | G6: 19.06.2025 | H6: 500 | I6: 3000 | J6: 3000 | L6: =SUM(H6:K6) -> 6500 | M6: 14500 | P6: 1500
F7: 6936 | G7: 10.09.2025 | I7: 4000 | L7: =SUM(H7:K7) -> 4000
L8: =SUM(H8:K8) -> 0
L9: =SUM(H9:K9) -> 0
L10: =SUM(H10:K10) -> 0
H11: =SUM(H6:H10) -> 500 | I11: =SUM(I6:I10) -> 7000 | J11: =SUM(J6:J10) -> 3000 | K11: =SUM(K6:K10) -> 0 | L11: =SUM(L6:L10) -> 10500 | N11: =M6-L11 -> 4000 | P11: =SUM(P6:P10) -> 1500
A12: 2 | B12: Mohammed Sohel Mohd Hanif, at. Bilal Nagar Dongaon, Buldhana, 7385604253 | C12: C-26 | D12: B.ed II Year | E12: 11.07.2025 to 11.05.2026 | F12: 6804 | G12: 17.07.2025 | H12: 500 | I12: 3000 | L12: =SUM(H12:K12) -> 3500 | M12: 14500 | O12: UPI | P12: 1500
F13: 7012 | G13: 08.10.2025 | I13: 6500 | J13: 3000 | L13: =SUM(H13:K13) -> 9500
L14: =SUM(H14:K14) -> 0
L15: =SUM(H15:K15) -> 0
L16: =SUM(H16:K16) -> 0
H17: =SUM(H12:H16) -> 500 | I17: =SUM(I12:I16) -> 9500 | J17: =SUM(J12:J16) -> 3000 | K17: =SUM(K12:K16) -> 0 | L17: =SUM(L12:L16) -> 13000 | N17: =M12-L17 -> 1500 | P17: =SUM(P12:P16) -> 1500
A18: 3 | B18: Shaikh Zeeshan Shaikh Naser, at. Walti, Tq. Chikhli Dist. Buldhana, 9960605816, 8459981921 | C18: B-07 | D18: B.ed I Year | E18: 18.08.2025 to 18.06.2026 | F18: 6880 | G18: 18.08.2025 | H18: 500 | I18: 1000 | L18: =SUM(H18:K18) -> 1500 | M18: 14500 | P18: 1500
F19: 6998 | G19: 03.10.2025 | I19: 1000 | J19: 3000 | L19: =SUM(H19:K19) -> 4000
F20: 7027 | G20: 16.10.2025 | I20: 9000 | L20: =SUM(H20:K20) -> 9000
L21: =SUM(H21:K21) -> 0
L22: =SUM(H22:K22) -> 0
H23: =SUM(H18:H22) -> 500 | I23: =SUM(I18:I22) -> 11000 | J23: =SUM(J18:J22) -> 3000 | K23: =SUM(K18:K22) -> 0 | L23: =SUM(L18:L22) -> 14500 | N23: =M18-L23 -> 0 | P23: =SUM(P18:P22) -> 1500
A24: 4 | B24: Abdul Rahman Shaikh Mohammed, at. Indra Nagar, Dongaon, Tq. Mehkar Dist. Buldhana, 9850154578, 9763422576 | C24: C-26 | D24: B.ed I Year | E24: 20.07.2025 to 20.05.2026 | F24: 6812 | G24: 19.07.2025 | H24: 500 | I24: 3000 | L24: =SUM(H24:K24) -> 3500 | M24: 14500 | O24: UPI | P24: 1500
F25: 6980 | G25: 23.09.2025 | I25: 2000 | J25: 3000 | L25: =SUM(H25:K25) -> 5000
L26: =SUM(H26:K26) -> 0
L27: =SUM(H27:K27) -> 0
L28: =SUM(H28:K28) -> 0
H29: =SUM(H24:H28) -> 500 | I29: =SUM(I24:I28) -> 5000 | J29: =SUM(J24:J28) -> 3000 | K29: =SUM(K24:K28) -> 0 | L29: =SUM(L24:L28) -> 8500 | N29: =M24-L29 -> 6000 | P29: =SUM(P24:P28) -> 1500
A30: 5 | B30: Shaikh Sabir Shaikh Rauf, at. Laxmi Nagar,Dongaon, Tq. Mehkar Dist. Buldhana, 7219898104, | C30: C-26 | D30: B.ed II Year | E30: 23.08.2025 to 23.06.2026 | F30: 6897 | G30: 23.08.2025 | H30: 500 | I30: 1500 | J30: 3000 | L30: =SUM(H30:K30) -> 5000 | M30: 14500
L31: =SUM(H31:K31) -> 0
L32: =SUM(H32:K32) -> 0
L33: =SUM(H33:K33) -> 0
L34: =SUM(H34:K34) -> 0
H35: =SUM(H30:H34) -> 500 | I35: =SUM(I30:I34) -> 1500 | J35: =SUM(J30:J34) -> 3000 | K35: =SUM(K30:K34) -> 0 | L35: =SUM(L30:L34) -> 5000 | N35: =M30-L35 -> 9500 | P35: =SUM(P30:P34) -> 0
A36: 6 | B36: Ansari Abdul Musaddique, At. Hayat Colony , Pathri, Dist Parbhani, 7387064544 | C36: C-11 | D36: B.ed II Year | E36: 21.07.2025 to 21.05.2026 | F36: 6923 | G36: 04.09.2025 | H36: 500 | I36: 3500 | L36: =SUM(H36:K36) -> 4000 | M36: 14500 | O36: Old Student
L37: =SUM(H37:K37) -> 0
L38: =SUM(H38:K38) -> 0
L39: =SUM(H39:K39) -> 0
L40: =SUM(H40:K40) -> 0
...

Sheet M.Sc I & II 
A1: Dr.Rafiq Zakaria Campus
A2: Maulana Azad Complex of Hostel
A3: Dr.Rafiq Zakaria Marg, Rauza Bagh, Aurangabad
A4: Individual Register (M.Sc I & II Year) for the Academic Year 2025 - 2026 'A' Wing
A5: Sr.No | B5: Name of Student & Mobile | C5: Wing & Room | D5: Class | E5: Date of Joining | F5: Receipt No. | G5: Receipt Date | H5: Regi. Fee | I5: Room Rent | J5: Water & Electricity | K5: Others Activity | L5: Total Fees Collection | M5: Approved Hostel Fees | N5: Outstanding Fee | O5: Remark | P5: Security Deposit
A6: 1 | B6: Pathan Maheboob Khan Atmeer colony Darghr Road Dist.Parbhani 9552397069, 8482933593 | C6: A-02 | D6: M.Sc. II Zool. HL | E6: 02.07.2025 to 02.05.2026 | F6: 6805 | G6: 17.07.2025 | H6: 500 | I6: 6500 | J6: 3000 | L6: =SUM(H6:K6) -> 10000 | M6: 17500 | O6: Old Student
F7: 6806 | G7: 17.07.2025 | I7: 7500 | L7: =SUM(H7:K7) -> 7500 | O7: UPI
L8: =SUM(H8:K8) -> 0
L9: =SUM(H9:K9) -> 0
L10: =SUM(H10:K10) -> 0
H11: =SUM(H6:H10) -> 500 | I11: =SUM(I6:I10) -> 14000 | J11: =SUM(J6:J10) -> 3000 | K11: =SUM(K6:K10) -> 0 | L11: =SUM(L6:L10) -> 17500 | N11: =M6-L11 -> 0
L12: =SUM(H12:K12) -> 0
L13: =SUM(H13:K13) -> 0
L14: =SUM(H14:K14) -> 0
L15: =SUM(H15:K15) -> 0
L16: =SUM(H16:K16) -> 0
H17: =SUM(H12:H16) -> 0 | I17: =SUM(I12:I16) -> 0 | J17: =SUM(J12:J16) -> 0 | K17: =SUM(K12:K16) -> 0 | L17: =SUM(L12:L16) -> 0 | N17: =M12-L17 -> 0
L18: =SUM(H18:K18) -> 0
L19: =SUM(H19:K19) -> 0
L20: =SUM(H20:K20) -> 0
L21: =SUM(H21:K21) -> 0
L22: =SUM(H22:K22) -> 0
F23: Total | H23: =SUM(H18:H22) -> 0 | I23: =SUM(I18:I22) -> 0 | J23: =SUM(J18:J22) -> 0 | K23: =SUM(K18:K22) -> 0 | L23: =SUM(L18:L22) -> 0 | N23: =M18-L23 -> 0 | P23: =SUM(P18:P22) -> 0
L24: =SUM(H24:K24) -> 0
L25: =SUM(H25:K25) -> 0
L26: =SUM(H26:K26) -> 0
L27: =SUM(H27:K27) -> 0
L28: =SUM(H28:K28) -> 0
F29: Total | H29: =SUM(H24:H28) -> 0 | I29: =SUM(I24:I28) -> 0 | J29: =SUM(J24:J28) -> 0 | K29: =SUM(K24:K28) -> 0 | L29: =SUM(L24:L28) -> 0 | N29: =M24-L29 -> 0 | P29: =SUM(P24:P28) -> 0
A30: Total Fees Collection | H30: =+H29+H23+H17+H11 -> 500 | I30: =+I29+I23+I17+I11 -> 14000 | J30: =+J29+J23+J17+J11 -> 3000 | K30: =+K29+K23+K17+K11 -> 0 | L30: =+L29+L23+L17+L11 -> 17500 | M30: =+M24+M18+M12+M6 -> 17500 | N30: =+N29+N23+N17+N11 -> 0 | P30: =+P29+P23+P17+P11 -> 0
A32: NOTE:

Sheet M.Sc I & II  (B)
A1: Dr.Rafiq Zakaria Campus
A2: Maulana Azad Complex of Hostel
A3: Dr.Rafiq Zakaria Marg, Rauza Bagh, Aurangabad
A4: Individual Register (M.Sc I & II Year) for the Academic Year 2025 - 2026 'B & C' Wing
A5: Sr.No | B5: Name of Student & Mobile | C5: Wing & Room | D5: Class | E5: Date of Joining | F5: Receipt No. | G5: Receipt Date | H5: Regi. Fee | I5: Room Rent | J5: Water & Electricity Charges | K5: Other Activity | L5: Total Fees Collection | M5: Approved Hostel Fees | N5: Outstanding Fee | O5: Remark | P5: Security Deposit
A6: 1 | B6: Ashish Prbhakar Sathe, at Lonar Dist. Buldhana, 9763784329, 9022504314 | C6: C-22 | D6: MSc. Micro.II | E6: 21.05.2025 to 21.03.2026 | F6: 6694 | G6: 09.06.2025 | H6: 500 | I6: 1000 | L6: =SUM(H6:K6) -> 1500 | M6: 1500 | P6: 1500
L7: =SUM(H7:K7) -> 0 | O7: Admission cancelled
L8: =SUM(H8:K8) -> 0 | O8: on 28.06.2025
L9: =SUM(H9:K9) -> 0
L10: =SUM(H10:K10) -> 0
H11: =SUM(H6:H10) -> 500 | I11: =SUM(I6:I10) -> 1000 | J11: =SUM(J6:J10) -> 0 | K11: =SUM(K6:K10) -> 0 | L11: =SUM(L6:L10) -> 1500 | N11: =M6-L11 -> 0
A12: 2 | B12: Zaheer Baghban Badruddin Baba nagar Shellal Raod Nideban, Udgir Dist. Latur 9130245277 | C12: B-01 | D12: MSc. Micro.I | E12: 11.11.2025 to 11.09.2026 | F12: 7063 | G12: 11.11.2025 | H12: 500 | I12: 2000 | J12: 3000 | L12: =SUM(H12:K12) -> 5500 | M12: 14500 | P12: 1500
L13: =SUM(H13:K13) -> 0
L14: =SUM(H14:K14) -> 0
L15: =SUM(H15:K15) -> 0
L16: =SUM(H16:K16) -> 0
H17: =SUM(H12:H16) -> 500 | I17: =SUM(I12:I16) -> 2000 | J17: =SUM(J12:J16) -> 3000 | K17: =SUM(K12:K16) -> 0 | L17: =SUM(L12:L16) -> 5500 | N17: =M12-L17 -> 9000
L18: =SUM(H18:K18) -> 0
L19: =SUM(H19:K19) -> 0
L20: =SUM(H20:K20) -> 0
L21: =SUM(H21:K21) -> 0
L22: =SUM(H22:K22) -> 0
H23: =SUM(H18:H22) -> 0 | I23: =SUM(I18:I22) -> 0 | J23: =SUM(J18:J22) -> 0 | K23: =SUM(K18:K22) -> 0 | L23: =SUM(L18:L22) -> 0 | N23: =M18-L23 -> 0
L24: =SUM(H24:K24) -> 0
L25: =SUM(H25:K25) -> 0
L26: =SUM(H26:K26) -> 0
L27: =SUM(H27:K27) -> 0
L28: =SUM(H28:K28) -> 0
